pub fn add(left: u64, right: u64) -> u64 {
    left + right
}

pub fn add_two(arg: i32) -> i32 {
    arg + 2
}

pub fn failed() -> Result<(), String> {
    Err(String::from("error!"))
}

pub struct Guess {
    value: i32,
}

impl Guess {
    pub fn new(value: i32) -> Guess {
        if value < 1 || value > 100 {
            //予想値は1から100の間でなければなりませんが、{}でした。
            panic!("Guess value must be between 1 and 100, got {}.", value);
        }

        Guess { value }
    }
}

#[derive(Debug)]
struct Rectangle {
    width: u32,
    height: u32,
}

impl Rectangle {
    fn can_hold(&self, other: &Rectangle) -> bool {
        self.width > other.width && self.height > other.height
    }
}

fn main() {}

#[cfg(test)]
mod tests {
    use super::*;

    #[test]
    fn exploration() {
        let result = add(2, 2);
        assert_eq!(result, 4);
    }

    #[test]
    fn larger_can_hold_smaller() {
        let larger = Rectangle {
            width: 8,
            height: 7,
        };
        let smaller = Rectangle {
            width: 5,
            height: 1,
        };

        assert!(larger.can_hold(&smaller));
    }

    #[test]
    fn smaller_cannot_hold_larger() {
        let larger = Rectangle {
            width: 8,
            height: 7,
        };
        let smaller = Rectangle {
            width: 5,
            height: 1,
        };

        assert!(!smaller.can_hold(&larger));
    }

    #[test]
    fn it_adds_two() {
        assert_eq!(4, add_two(2));
    }

    #[test]
    #[should_panic]
    fn greater_than_100() {
        Guess::new(200);
    }

    #[test]
    fn equal_to_100() {
        Guess::new(100);
    }

    #[test]
    fn it_works() -> Result<(), String> {
        if 2 + 2 == 4 {
            Ok(())
        } else {
            Err(String::from("two plus two does not equal four"))
        }
    }

    #[test]
    fn it_works_err() -> Result<(), String> {
        let result = failed(); //Errが返った場合、関数の戻り値がそのErrとなり、処理終了

        match result {
            Ok(_) => panic!("this should have failed"),
            Err(e) => Ok(()),
        }
    }
}
